Workbook

Sheet Сводная
A3: Сумма по полю Товарооборот, руб | B3: Недели
A4: Территория | B4: 18 | C4: 19 | D4: 20 | E4: 21 | F4: 22 | G4: 23 | H4: Общий итог
A5: Волгоград | B5: 36934095 | C5: 43307156 | D5: 41300679 | E5: 44172813 | F5: 46485094 | G5: 5800290 | H5: 218000127
A6: Екатеринбург | B6: 42828758 | C6: 46366010 | D6: 47079842 | E6: 49575288 | F6: 50729186 | G6: 6829921.5 | H6: 2.43409e+08
A7: Казань | B7: 17828216 | C7: 20974521 | D7: 23603355 | E7: 26815804 | F7: 27495690 | G7: 3865251 | H7: 120582837
A8: Кемерово | B8: 16029680 | C8: 19479056 | D8: 19724733 | E8: 20915751 | F8: 22579281 | G8: 2945035.5 | H8: 1.0167354e+08
A9: Краснодар | B9: 13955985 | C9: 16391856 | D9: 16732521 | E9: 17647479 | F9: 18595773 | G9: 2538967.5 | H9: 85862582
A10: Москва Восток | B10: 130713645 | C10: 1.5164204e+08 | D10: 135813990 | E10: 149589546 | F10: 151451013 | G10: 18914194 | H10: 738124428
A11: Москва Запад | B11: 136791225 | C11: 159695760 | D11: 142825023 | E11: 1.5751236e+08 | F11: 1.5785721e+08 | G11: 19465372 | H11: 7.7414695e+08
A12: Нижний Новгород | B12: 13145966 | C12: 17149980 | D12: 19963154 | E12: 20713983 | F12: 21605704 | G12: 3013512 | H12: 95592298
A13: Новосибирск | B13: 5746024.5 | C13: 7253572.5 | D13: 7841920.5 | E13: 8990269.5 | F13: 9909624 | G13: 1293219 | H13: 41034630
A14: Пермь | B14: 6961020 | C14: 8778597 | D14: 9036316.5 | E14: 10598445 | F14: 11902053 | G14: 1526608.5 | H14: 48803040
A15: Ростов-на-Дону | B15: 2008809 | C15: 5892277.5 | D15: 7382458.5 | E15: 8638525.5 | F15: 9328845 | G15: 1565632.5 | H15: 34816548
A16: Самара | F16: 2706253.5 | G16: 636345 | H16: 3342598.5
A17: Санкт-Петербург Север | B17: 233059077 | C17: 2.727625e+08 | D17: 269949999 | E17: 2.7553943e+08 | F17: 2.9215505e+08 | G17: 37257840 | H17: 1.3807239e+09
A18: Санкт-Петербург Юг | B18: 176269533 | C18: 2.0812839e+08 | D18: 1.9956962e+08 | E18: 2.0460881e+08 | F18: 2.1926593e+08 | G18: 27770092 | H18: 1.0356124e+09
A19: Тольятти | B19: 4531000.5 | C19: 6093688.5 | D19: 6439392 | E19: 7373379 | F19: 7762362 | G19: 1007742 | H19: 33207564
A20: Томск | F20: 493893 | G20: 389013 | H20: 882906
A21: Тюмень | F21: 4861708.5 | G21: 802447.5 | H21: 5664156
A22: Уфа | F22: 468835.5 | G22: 410892 | H22: 879727.5
A23: Общий итог | B23: 836803032 | C23: 9.8391541e+08 | D23: 9.4726301e+08 | E23: 1.0026919e+09 | F23: 1.0556535e+09 | G23: 1.3603238e+08 | H23: 4.9623592e+09
A26: ТОП-3 территорий по доле в общем товарообороте | B26: Сумма по полю Товарооборот, руб
A27: Санкт-Петербург Север | B27: 0.27823941
A28: Санкт-Петербург Юг | B28: 0.20869355
A29: Москва Запад | B29: 0.15600381
A30: Москва Восток | B30: 0.14874466
A31: Екатеринбург | B31: 0.049051065
A32: Волгоград | B32: 0.043930743
A33: Казань | B33: 0.024299498
A34: Кемерово | B34: 0.020488951
A35: Нижний Новгород | B35: 0.019263478
A36: Краснодар | B36: 0.017302774
A37: Пермь | B37: 0.0098346447
A38: Новосибирск | B38: 0.0082691777
... A45: Общий итог | B45: 1
A50: Сумма по полю Товарооборот на склад | B50: Недели
A51: Топ-3 территорий по товарообороту на склад за последнюю неделю | B51: 23 | C51: Общий итог
A52: Москва Восток | B52: 350262.86 | C52: 350262.86
A53: Москва Запад | B53: 329921.57 | C53: 329921.57
A54: Санкт-Петербург Север | B54: 302909.27 | C54: 302909.27
...

Sheet Сводная график
A3: Названия строк | B3: Сумма по полю Товарооборот, руб | C3: Сумма по полю Товарооборот на склад
A4: 18 | B4: 836803032 | C4: 15050189
A5: 19 | B5: 9.8391541e+08 | C5: 17810867
A6: 20 | B6: 9.4726301e+08 | C6: 17504431
A7: 21 | B7: 1.0026919e+09 | C7: 18752595
A8: 22 | B8: 1.0556535e+09 | C8: 20458987
A9: 23 | B9: 1.3603238e+08 | C9: 2786041.4
A10: Общий итог | B10: 4.9623592e+09 | C10: 92363110

Sheet Лист1
A1: Дата | B1: Территория | C1: Товарооборот, шт | D1: Товарооборот, руб | E1: Количество складов | F1: Количество заказов | G1: Количество клиентов | H1: Товарооборот на склад | I1: Неделя
A2: 43982 | B2: Самара | C2: 7944 | D2: 623971.5 | E2: =SUMIFS(Лист2!C:C,Лист2!A:A,A2,Лист2!B:B,B2) -> 15 | F2: =SUMIFS(Лист2!D:D,Лист2!A:A,A2,Лист2!B:B,B2) -> 441 | G2: =SUMIFS(Лист2!E:E,Лист2!A:A,A2,Лист2!B:B,B2) -> 368 | H2: =D2/E2 -> 41598.1 | I2: =WEEKNUM(A2,21) -> 22
A3: 43981 | B3: Самара | C3: 10029 | D3: 787101 | E3: =SUMIFS(Лист2!C:C,Лист2!A:A,A3,Лист2!B:B,B3) -> 15 | F3: =SUMIFS(Лист2!D:D,Лист2!A:A,A3,Лист2!B:B,B3) -> 490 | G3: =SUMIFS(Лист2!E:E,Лист2!A:A,A3,Лист2!B:B,B3) -> 409 | H3: =D3/E3 -> 52473.4 | I3: =WEEKNUM(A3,21) -> 22
A4: 43979 | B4: Самара | C4: 8536.5 | D4: 643944 | E4: =SUMIFS(Лист2!C:C,Лист2!A:A,A4,Лист2!B:B,B4) -> 15 | F4: =SUMIFS(Лист2!D:D,Лист2!A:A,A4,Лист2!B:B,B4) -> 464 | G4: =SUMIFS(Лист2!E:E,Лист2!A:A,A4,Лист2!B:B,B4) -> 390 | H4: =D4/E4 -> 42929.6 | I4: =WEEKNUM(A4,21) -> 22
A5: 43967 | B5: Кемерово | C5: 38947.5 | D5: 3395892 | E5: =SUMIFS(Лист2!C:C,Лист2!A:A,A5,Лист2!B:B,B5) -> 21 | F5: =SUMIFS(Лист2!D:D,Лист2!A:A,A5,Лист2!B:B,B5) -> 2145 | G5: =SUMIFS(Лист2!E:E,Лист2!A:A,A5,Лист2!B:B,B5) -> 1947 | H5: =D5/E5 -> 161709.14 | I5: =WEEKNUM(A5,21) -> 20
A6: 43970 | B6: Кемерово | C6: 31842 | D6: 2771116.5 | E6: =SUMIFS(Лист2!C:C,Лист2!A:A,A6,Лист2!B:B,B6) -> 21 | F6: =SUMIFS(Лист2!D:D,Лист2!A:A,A6,Лист2!B:B,B6) -> 1860 | G6: =SUMIFS(Лист2!E:E,Лист2!A:A,A6,Лист2!B:B,B6) -> 1704 | H6: =D6/E6 -> 131957.93 | I6: =WEEKNUM(A6,21) -> 21
A7: 43968 | B7: Кемерово | C7: 32023.5 | D7: 2882458.5 | E7: =SUMIFS(Лист2!C:C,Лист2!A:A,A7,Лист2!B:B,B7) -> 21 | F7: =SUMIFS(Лист2!D:D,Лист2!A:A,A7,Лист2!B:B,B7) -> 1874 | G7: =SUMIFS(Лист2!E:E,Лист2!A:A,A7,Лист2!B:B,B7) -> 1705 | H7: =D7/E7 -> 137259.93 | I7: =WEEKNUM(A7,21) -> 20
A8: 43960 | B8: Кемерово | C8: 31147.5 | D8: 2831019 | E8: =SUMIFS(Лист2!C:C,Лист2!A:A,A8,Лист2!B:B,B8) -> 21 | F8: =SUMIFS(Лист2!D:D,Лист2!A:A,A8,Лист2!B:B,B8) -> 1735 | G8: =SUMIFS(Лист2!E:E,Лист2!A:A,A8,Лист2!B:B,B8) -> 1568 | H8: =D8/E8 -> 134810.43 | I8: =WEEKNUM(A8,21) -> 19
A9: 43955 | B9: Кемерово | C9: 25566 | D9: 2372310 | E9: =SUMIFS(Лист2!C:C,Лист2!A:A,A9,Лист2!B:B,B9) -> 20 | F9: =SUMIFS(Лист2!D:D,Лист2!A:A,A9,Лист2!B:B,B9) -> 1519 | G9: =SUMIFS(Лист2!E:E,Лист2!A:A,A9,Лист2!B:B,B9) -> 1372 | H9: =D9/E9 -> 118615.5 | I9: =WEEKNUM(A9,21) -> 19
A10: 43950 | B10: Кемерово | C10: 29319 | D10: 2623480.5 | E10: =SUMIFS(Лист2!C:C,Лист2!A:A,A10,Лист2!B:B,B10) -> 18 | F10: =SUMIFS(Лист2!D:D,Лист2!A:A,A10,Лист2!B:B,B10) -> 1684 | G10: =SUMIFS(Лист2!E:E,Лист2!A:A,A10,Лист2!B:B,B10) -> 1528 | H10: =D10/E10 -> 145748.92 | I10: =WEEKNUM(A10,21) -> 18
A11: 43953 | B11: Кемерово | C11: 29031 | D11: 2711247 | E11: =SUMIFS(Лист2!C:C,Лист2!A:A,A11,Лист2!B:B,B11) -> 18 | F11: =SUMIFS(Лист2!D:D,Лист2!A:A,A11,Лист2!B:B,B11) -> 1708 | G11: =SUMIFS(Лист2!E:E,Лист2!A:A,A11,Лист2!B:B,B11) -> 1534 | H11: =D11/E11 -> 150624.83 | I11: =WEEKNUM(A11,21) -> 18
A12: 43977 | B12: Кемерово | C12: 33423 | D12: 2970330 | E12: =SUMIFS(Лист2!C:C,Лист2!A:A,A12,Лист2!B:B,B12) -> 20 | F12: =SUMIFS(Лист2!D:D,Лист2!A:A,A12,Лист2!B:B,B12) -> 2044 | G12: =SUMIFS(Лист2!E:E,Лист2!A:A,A12,Лист2!B:B,B12) -> 1863 | H12: =D12/E12 -> 148516.5 | I12: =WEEKNUM(A12,21) -> 22
A13: 43952 | B13: Кемерово | C13: 32487 | D13: 3031254 | E13: =SUMIFS(Лист2!C:C,Лист2!A:A,A13,Лист2!B:B,B13) -> 18 | F13: =SUMIFS(Лист2!D:D,Лист2!A:A,A13,Лист2!B:B,B13) -> 1826 | G13: =SUMIFS(Лист2!E:E,Лист2!A:A,A13,Лист2!B:B,B13) -> 1633 | H13: =D13/E13 -> 168403 | I13: =WEEKNUM(A13,21) -> 18
... A505: 43983 | B505: Новосибирск | C505: 14238 | D505: 1293219 | E505: =SUMIFS(Лист2!C:C,Лист2!A:A,A505,Лист2!B:B,B505) -> 18 | F505: =SUMIFS(Лист2!D:D,Лист2!A:A,A505,Лист2!B:B,B505) -> 923 | G505: =SUMIFS(Лист2!E:E,Лист2!A:A,A505,Лист2!B:B,B505) -> 824 | H505: =D505/E505 -> 71845.5 | I505: =WEEKNUM(A505,21) -> 23

Sheet Лист2
A1: Дата | B1: Территория | C1: Количество складов | D1: Количество заказов | E1: Количество клиентов
A2: 43949 | B2: Волгоград | C2: 36 | D2: 4923 | E2: 4560
A3: 43949 | B3: Екатеринбург | C3: 31 | D3: 5465 | E3: 5096
A4: 43949 | B4: Казань | C4: 19 | D4: 1846 | E4: 1681
A5: 43949 | B5: Кемерово | C5: 18 | D5: 1539 | E5: 1404
A6: 43949 | B6: Краснодар | C6: 18 | D6: 1505 | E6: 1368
A7: 43949 | B7: Москва Восток | C7: 54 | D7: 12306 | E7: 11532
A8: 43949 | B8: Москва Запад | C8: 59 | D8: 12943 | E8: 12072
A9: 43949 | B9: Нижний Новгород | C9: 17 | D9: 1439 | E9: 1265
A10: 43949 | B10: Новосибирск | C10: 15 | D10: 636 | E10: 547
A11: 43949 | B11: Пермь | C11: 15 | D11: 780 | E11: 690
A12: 43949 | B12: Санкт-Петербург Север | C12: 125 | D12: 20914 | E12: 19479
A13: 43949 | B13: Санкт-Петербург Юг | C13: 128 | D13: 16450 | E13: 15320
... A505: 43983 | B505: Уфа | C505: 6 | D505: 237 | E505: 175
